<?xml version="1.0"?>
<robot name="my_arm" xmlns:xacro="http://ros.org/wiki/xacro">

  <material name="blue">
    <color rgba="0 0 0.8 1"/>
  </material>

  <material name="black">
    <color rgba="0 0 0 1"/>
  </material>

  <material name="white">
    <color rgba="1 1 1 1"/>
  </material>

  <!-- Constants define -->
  <xacro:property name="M_PI" value="3.1415"/>
  <xacro:property name="motor_mass" value="0.0535"/>
  <xacro:property name="F4_mass" value="0.015"/>
  <xacro:property name="F3_mass" value="0.009"/>
  <xacro:property name="F2_mass" value="0.009"/>
  <xacro:property name="gripper_base_mass" value="0.01"/>
  <xacro:property name="gripper_finger_mass" value="0.005"/>
  <!-- end Constants define -->

  <!-- First motor -->
  <link name="arm_base">
    <visual>
      <geometry>
        <mesh filename="package://dynamixel_arm/urdf/meshes/ax12_box.stl" scale="0.001 0.001 0.001"/>
      </geometry>
      <origin rpy="0 0 0" xyz="0 0 0.0385"/>
    </visual>
    <collision>
      <geometry>
        <mesh filename="package://dynamixel_arm/urdf/meshes/ax12_box.stl" scale="0.001 0.001 0.001"/>
      </geometry>
      <origin rpy="0 0 0" xyz="0 0 0"/>
    </collision>
    <inertia>
      <mass value="${motor_mass}"/>
      <inertia ixx="1.0" ixy="0.0" ixz="0.0" iyy="1.0" iyz="0.0" izz="1.0"/>
    </inertia>
  </link>
  <!-- end First motor -->
  <!-- FP04-F4 -->
  <link name="frame_4">
    <visual>
      <geometry>
        <mesh filename="package://dynamixel_arm/urdf/meshes/F4.stl" scale="0.001 0.001 0.001"/>
      </geometry>
      <origin rpy="0 0 0" xyz="0 0 0"/>
    </visual>
    <collision>
      <geometry>
        <mesh filename="package://dynamixel_arm/urdf/meshes/F4.stl" scale="0.001 0.001 0.001"/>
      </geometry>
      <origin rpy="0 0 0" xyz="0 0 0"/>
    </collision>
    <inertia>
      <mass value="${F4_mass}"/>
      <inertia ixx="1.0" ixy="0.0" ixz="0.0" iyy="1.0" iyz="0.0" izz="1.0"/>
    </inertia>
  </link>
  <joint name="pan_joint" type="revolute">
    <axis xyz="0 1 0"/>
    <origin rpy="0 0 0" xyz="0 0 0.0385"/>
    <limit effort="1000.0" upper="1.948" lower="-1.743" velocity="2.0"/>
    <parent link="arm_base"/>
    <child link="frame_4"/>
  </joint>
  <!-- end FP04-F4 -->
  <!-- FP04-F3 -->
  <link name="frame_3_1">
    <visual>
      <geometry>
        <mesh filename="package://dynamixel_arm/urdf/meshes/F3.stl" scale="0.001 0.001 0.001"/>
      </geometry>
      <origin rpy="0 ${M_PI} 0" xyz="0 0 0"/>
    </visual>
    <collision>
      <geometry>
        <mesh filename="package://dynamixel_arm/urdf/meshes/F3.stl" scale="0.001 0.001 0.001"/>
      </geometry>
      <origin rpy="0 ${M_PI} 0" xyz="0 0 0"/>
    </collision>
    <inertia>
      <mass value="${F3_mass}"/>
      <inertia ixx="1.0" ixy="0.0" ixz="0.0" iyy="1.0" iyz="0.0" izz="1.0"/>
    </inertia>
  </link>
  <joint name="frame4toframe3_1" type="fixed">
    <origin rpy="0 0 0" xyz="0 0 0.052"/>
    <parent link="frame_4"/>
    <child link="frame_3_1"/>
  </joint>
  <!-- end FP04-F3 -->
  <!-- Second motor -->
  <link name="tilt_motor">
    <visual>
      <geometry>
        <mesh filename="package://dynamixel_arm/urdf/meshes/ax12_box.stl" scale="0.001 0.001 0.001"/>
      </geometry>
      <origin rpy="0 0 0" xyz="0 0 0.0385"/>
    </visual>
    <collision>
      <geometry>
        <mesh filename="package://dynamixel_arm/urdf/meshes/ax12_box.stl" scale="0.001 0.001 0.001"/>
      </geometry>
      <origin rpy="0 0 0" xyz="0 0 0"/>
    </collision>
    <inertia>
      <mass value="${motor_mass}"/>
      <inertia ixx="1.0" ixy="0.0" ixz="0.0" iyy="1.0" iyz="0.0" izz="1.0"/>
    </inertia>
  </link>
  <joint name="tilt_joint" type="revolute">
    <axis xyz="0 1 0"/>
    <origin rpy="0 0 0" xyz="0 0 0.002"/>
    <limit effort="1000.0" upper="1.79" lower="-1.626" velocity="2.0"/>
    <parent link="frame_3_1"/>
    <child link="tilt_motor"/>
  </joint>
  <!-- end Second motor -->
  <!-- FP04-F2 -->
  <link name="frame_2">
    <visual>
      <geometry>
        <mesh filename="package://dynamixel_arm/urdf/meshes/F2.stl" scale="0.001 0.001 0.001"/>
      </geometry>
      <origin rpy="0 0 0" xyz="0 0 0"/>
    </visual>
    <collision>
      <geometry>
        <mesh filename="package://dynamixel_arm/urdf/meshes/F2.stl" scale="0.001 0.001 0.001"/>
      </geometry>
      <origin rpy="0 0 0" xyz="0 0 0"/>
    </collision>
    <inertia>
      <mass value="${F2_mass}"/>
      <inertia ixx="1.0" ixy="0.0" ixz="0.0" iyy="1.0" iyz="0.0" izz="1.0"/>
    </inertia>
  </link>
  <joint name="frame2totilt_motor" type="fixed">
    <origin rpy="0 0 0" xyz="0 0 0.0385"/>
    <parent link="tilt_motor"/>
    <child link="frame_2"/>
  </joint>
  <!-- end FP04-F2 -->
  <!-- FP04-F3 -->
  <link name="frame_3_2">
    <visual>
      <geometry>
        <mesh filename="package://dynamixel_arm/urdf/meshes/F3.stl" scale="0.001 0.001 0.001"/>
      </geometry>
      <origin rpy="0 ${M_PI} ${M_PI/2}" xyz="0 0 0"/>
    </visual>
    <collision>
      <geometry>
        <mesh filename="package://dynamixel_arm/urdf/meshes/F3.stl" scale="0.001 0.001 0.001"/>
      </geometry>
      <origin rpy="0 ${M_PI} 0" xyz="0 0 0"/>
    </collision>
    <inertia>
      <mass value="${F3_mass}"/>
      <inertia ixx="1.0" ixy="0.0" ixz="0.0" iyy="1.0" iyz="0.0" izz="1.0"/>
    </inertia>
  </link>
  <joint name="frame2toframe3_2" type="fixed">
    <origin rpy="0 0 0" xyz="0 0 0.026"/>
    <parent link="frame_2"/>
    <child link="frame_3_2"/>
  </joint>
  <!-- end FP04-F3 -->
  <!-- Third motor -->
    <link name="gripper_motor">
    <visual>
      <geometry>
        <mesh filename="package://dynamixel_arm/urdf/meshes/ax12_box.stl" scale="0.001 0.001 0.001"/>
      </geometry>
      <origin rpy="0 0 ${-M_PI/2}" xyz="0 0 0.0385"/>
    </visual>
    <collision>
      <geometry>
        <mesh filename="package://dynamixel_arm/urdf/meshes/ax12_box.stl" scale="0.001 0.001 0.001"/>
      </geometry>
      <origin rpy="0 0 ${M_PI/2}" xyz="0 0 0"/>
    </collision>
    <inertia>
      <mass value="${motor_mass}"/>
      <inertia ixx="1.0" ixy="0.0" ixz="0.0" iyy="1.0" iyz="0.0" izz="1.0"/>
    </inertia>
  </link>
  <joint name="gripper_joint" type="fixed">
    <origin rpy="0 0 0" xyz="0 0 0.002"/>
    <parent link="frame_3_2"/>
    <child link="gripper_motor"/>
  </joint>
  <!-- end Third motor -->
  <!-- Gripper base -->
  <link name="gripper_base">
    <visual>
      <geometry>
        <mesh filename="package://dynamixel_arm/urdf/meshes/pincher_finger_base.stl" scale="0.01 0.01 0.01"/>
      </geometry>
      <origin rpy="0 0 ${M_PI/2}" xyz="0 0 0"/>
    </visual>
    <collision>
      <geometry>
        <mesh filename="package://dynamixel_arm/urdf/meshes/pincher_finger_base.stl" scale="0.01 0.01 0.01"/>
      </geometry>
      <origin rpy="0 0 ${M_PI/2}" xyz="0 0 0"/>
    </collision>
    <inertia>
      <mass value="${gripper_base_mass}"/>
      <inertia ixx="1.0" ixy="0.0" ixz="0.0" iyy="1.0" iyz="0.0" izz="1.0"/>
    </inertia>
  </link>
  <joint name="gripper_motor2base" type="fixed">
    <origin rpy="0 0 0" xyz="0.0175 0 0.04"/>
    <parent link="gripper_motor"/>
    <child link="gripper_base"/>
  </joint>
  <!-- end Gripper base -->
  <!-- Finger left -->
  <link name="finger_left">
    <visual>
      <geometry>
        <mesh filename="package://dynamixel_arm/urdf/meshes/pincher_finger.stl" scale="0.01 0.01 0.01"/>
      </geometry>
      <origin rpy="0 0 ${M_PI}" xyz="0.012 0 0"/>
    </visual>
    <collision>
      <geometry>
        <mesh filename="package://dynamixel_arm/urdf/meshes/pincher_finger.stl" scale="0.01 0.01 0.01"/>
      </geometry>
      <origin rpy="0 0 ${M_PI}" xyz="0.012 0 0"/>
    </collision>
    <inertia>
      <mass value="${gripper_finger_mass}"/>
      <inertia ixx="1.0" ixy="0.0" ixz="0.0" iyy="1.0" iyz="0.0" izz="1.0"/>
    </inertia>
  </link>
  <joint name="base_to_left" type="prismatic">
    <axis rpy="0 0 0" xyz="1 0 0"/>
    <limit effort="1000.0" upper="0.013" lower="0.0" velocity="1.0"/>
    <origin rpy="${-M_PI/2} 0 ${-M_PI/2}" xyz="0 0.035 0"/>
    <parent link="gripper_base"/>
    <child link="finger_left"/>
  </joint>
  <!-- end Finger left -->
  <!-- Finger right -->
    <link name="finger_right">
    <visual>
      <geometry>
        <mesh filename="package://dynamixel_arm/urdf/meshes/pincher_finger.stl" scale="0.01 0.01 0.01"/>
      </geometry>
      <origin rpy="0 0 ${M_PI}" xyz="0.012 0 0"/>
    </visual>
    <collision>
      <geometry>
        <mesh filename="package://dynamixel_arm/urdf/meshes/pincher_finger.stl" scale="0.01 0.01 0.01"/>
      </geometry>
      <origin rpy="0 0 ${M_PI}" xyz="0.012 0 0"/>
    </collision>
    <inertia>
      <mass value="${gripper_finger_mass}"/>
      <inertia ixx="1.0" ixy="0.0" ixz="0.0" iyy="1.0" iyz="0.0" izz="1.0"/>
    </inertia>
  </link>
  <joint name="base_to_right" type="prismatic">
    <axis rpy="0 0 0" xyz="1 0 0"/>
    <limit effort="1000.0" upper="0.013" lower="0.0" velocity="1.0"/>
    <origin rpy="${M_PI/2} 0 ${M_PI/2}" xyz="0 -0.035 0"/>
    <parent link="gripper_base"/>
    <child link="finger_right"/>
  </joint>
  <!-- end Finger right --> 
  <!-- TCP -->
  <link name="tcp">
  </link>
  <joint name="base_to_tcp" type="fixed">
    <origin rpy="0 0 0" xyz="0.04 0 0"/>
    <parent link="gripper_base"/>
    <child link="tcp"/>
  </joint>
</robot>
